<?xml version='1.0' encoding='utf8'?>
<mujoco model="gen3_robotiq_2f_85">
        <compiler angle="radian" meshdir="gen3" />
        <size njmax="500" nconmax="500" />
        <asset>
            <mesh name="base_link" file="base_link.STL" />
            <mesh name="shoulder_link" file="shoulder_link.STL" />
            <mesh name="half_arm_1_link" file="half_arm_1_link.STL" />
            <mesh name="half_arm_2_link" file="half_arm_2_link.STL" />
            <mesh name="forearm_link" file="forearm_link.STL" />
            <mesh name="spherical_wrist_1_link" file="spherical_wrist_1_link.STL" />
            <mesh name="spherical_wrist_2_link" file="spherical_wrist_2_link.STL" />
            <mesh name="bracelet_link" file="bracelet_link.STL" />
            <mesh name="robotiq_85_base_link" file="robotiq_85_base_link.stl" />
            <mesh name="robotiq_85_knuckle_link" file="robotiq_85_knuckle_link.stl" />
            <mesh name="robotiq_85_finger_link" file="robotiq_85_finger_link.stl" />
            <mesh name="robotiq_85_inner_knuckle_link" file="robotiq_85_inner_knuckle_link.stl" />
            <mesh name="robotiq_85_finger_tip_link" file="robotiq_85_finger_tip_link.stl" />
            <texture type="2d" name="texplane" builtin="checker" mark="cross" rgb1="0.8 0.9 1" rgb2="0.6 0.8 0.8" markrgb="0.8 0.8 0.8" width="512" height="512" />
            <material name="matplane" texture="texplane" texuniform="true" reflectance="0.3" />
        </asset>
        
        <option cone="elliptic" />
        
        <visual>        
            <global offwidth="480" offheight="480" />
        </visual>
        
        <default>        
            
            <default class="GEN3">
                
                <joint type="hinge" armature="0.01" damping="0" />
            </default>
            <default class="2F-85">
                <joint type="hinge" armature="0.08" damping="5" />
            </default>
        </default>

        <worldbody>
            <geom size="0 0 0.1" pos="0 0 0" type="plane" material="matplane" />
            <light pos="0 0 100" dir="0 0 -1" diffuse="0.5 0.5 0.5" castshadow="false" />  

            <body name="Gen3_robot" pos="-0.07 0 0.82">
                <geom type="mesh" rgba="0.75294 0.75294 0.75294 1" mesh="base_link" />
                <body name="shoulder_link" pos="0 0 0.15643" quat="-3.67321e-06 1 0 0">
                    <inertial pos="-2.3e-05 -0.010364 -0.07336" quat="0.707051 0.0451246 -0.0453544 0.704263" mass="1.3773" diaginertia="0.00488868 0.00457 0.00135132" />
                    <joint name="robot0:joint_1" pos="0 0 0" axis="0 0 1" class="GEN3" />
                    <geom type="mesh" rgba="0.75294 0.75294 0.75294 1" mesh="shoulder_link" />
                    <body name="half_arm_1_link" pos="0 0.005375 -0.12838" quat="0.707105 0.707108 0 0">
                        <inertial pos="-4.4e-05 -0.09958 -0.013278" quat="0.482348 0.516286 -0.516862 0.483366" mass="1.1636" diaginertia="0.0113017 0.011088 0.00102532" />
                        <joint name="robot0:joint_2" pos="0 0 0" axis="0 0 1" limited="true" range="-2.41 2.41" class="GEN3" />
                        <geom type="mesh" rgba="0.75294 0.75294 0.75294 1" mesh="half_arm_1_link" />
                        <body name="half_arm_2_link" pos="0 -0.21038 -0.006375" quat="0.707105 -0.707108 0 0">
                            <inertial pos="-4.4e-05 -0.006641 -0.117892" quat="0.706144 0.0213722 -0.0209128 0.707437" mass="1.1636" diaginertia="0.0111633 0.010932 0.00100671" />
                            <joint name="robot0:joint_3" pos="0 0 0" axis="0 0 1" class="GEN3" />
                            <geom type="mesh" rgba="0.75294 0.75294 0.75294 1" mesh="half_arm_2_link" />
                            <body name="forearm_link" pos="0 0.006375 -0.21038" quat="0.707105 0.707108 0 0">
                                <inertial pos="-1.8e-05 -0.075478 -0.015006" quat="0.483678 0.515961 -0.515859 0.483455" mass="0.9302" diaginertia="0.00834839 0.008147 0.000598606" />
                                <joint name="robot0:joint_4" pos="0 0 0" axis="0 0 1" limited="true" range="-2.66 2.66" class="GEN3" />
                                <geom type="mesh" rgba="0.75294 0.75294 0.75294 1" mesh="forearm_link" />
                                <body name="spherical_wrist_1_link" pos="0 -0.20843 -0.006375" quat="0.707105 -0.707108 0 0">
                                    <inertial pos="1e-06 -0.009432 -0.063883" quat="0.703558 0.0707492 -0.0707492 0.703558" mass="0.6781" diaginertia="0.00165901 0.001596 0.000346988" />
                                    <joint name="robot0:joint_5" pos="0 0 0" axis="0 0 1" class="GEN3" />
                                    <geom type="mesh" rgba="0.75294 0.75294 0.75294 1" mesh="spherical_wrist_1_link" />
                                    <body name="spherical_wrist_2_link" pos="0 0.00017505 -0.10593" quat="0.707105 0.707108 0 0">
                                        <inertial pos="1e-06 -0.045483 -0.00965" quat="0.44426 0.550121 -0.550121 0.44426" mass="0.6781" diaginertia="0.00170087 0.001641 0.00035013" />
                                        <joint name="robot0:joint_6" pos="0 0 0" axis="0 0 1" limited="true" range="-2.23 2.23" class="GEN3" />
                                        <geom type="mesh" rgba="0.75294 0.75294 0.75294 1" mesh="spherical_wrist_2_link" />
                                        <body name="bracelet_link" pos="0 -0.10593 -0.00017505" quat="0.707105 -0.707108 0 0">
                                            
                                            <camera name="realsense" pos="0.0275 -0.066 -0.0585" fovy="41" />
                                            <site name="robot0:0grip0" pos="0 0 -0.1" rgba="0 1 0 0" size="0.03 0.03 0.03" />
                                            
                                            <site name="robot0:grip" pos="0 0 -0.21" rgba="0 1 0 0" size="0.01 0.01 0.01" />
                                            
                                            
                                            <inertial pos="-0.000123659 -0.00501766 -0.047563" quat="0.992012 0.125472 -0.00415161 0.0123474" mass="1.13755" diaginertia="0.00201571 0.00187851 0.000969013" />
                                            <joint name="robot0:joint_7" pos="0 0 0" axis="0 0 1" class="GEN3" />
                                            <geom type="mesh" rgba="0.75294 0.75294 0.75294 1" mesh="bracelet_link" />
                                            <geom pos="0 0 -0.061525" quat="-0.5 0.500398 -0.499602 -0.5" type="mesh" mesh="robotiq_85_base_link" />
                                            
                                            <site name="gf1b_s" pos="-0.0126511 -1.01133e-05 -0.122955" size="0.002,0.002,0.002" />
                                            <site name="gf2b_s" pos="0.0127489 1.01133e-05 -0.122935" size="0.002,0.002,0.002" />
                                            
                                            
                                            <body name="gripper_finger1_knuckle_link" pos="-0.0305574 -2.43685e-05 -0.116454" quat="-0.500399 -0.499999 -0.500001 0.499601">
                                                <inertial pos="-0.00243606 -0.0187741 0" quat="0.647436 0.284299 -0.647436 0.284299" mass="0.0458" diaginertia="4.11145e-05 2.69913e-05 1.81232e-05" />
                                                <joint name="robot0:gripper_finger1_joint" pos="0 0 0" axis="0 0 1" damping="5" limited="true" range="0 0.804" class="2F-85" />
                                                <geom type="mesh" mesh="robotiq_85_knuckle_link" />
                                                <body name="gripper_finger1_knuckle2_link" pos="0 0 0">
                                                    <joint name="gripper_finger1_joint2" pos="-0.00408552 -0.031486 0" axis="0 0 1" limited="true" range="0 0.804" class="2F-85" />
                                                    <geom pos="-0.00408552 -0.031486 0" type="mesh" mesh="robotiq_85_finger_link" />
                                                    <body name="gripper_finger1_finger_tip_link" pos="0.05 -0.0200 0">
                                                        <inertial pos="0 0 0" quat="0 0.707107 0 0.707107" mass="0.019555" diaginertia="6e-06 5e-06 2e-06" />
                                                        <joint name="gripper_finger1_finger_tip_joint" pos="-0.0066 -0.017245 0" stiffness="50" axis="0 0 1" limited="false" range="0 0.804" class="2F-85" />
                                                        <geom type="mesh" mesh="robotiq_85_finger_tip_link" friction="0.0 0.00 0.0000" solimp="0.99 0.99 0.01" solref="0.01 1" condim="4" margin="0.0" />
                                                        <geom name="tip_left_pivot" pos="0.038 0.00925 0.00" size="0.0018" type="sphere" rgba="0 0.7 0.1 1" friction="1.2 0.005 0.0001" solimp="0.99 0.99 0.01" solref="0.01 1" condim="4" margin="0.0" />
                                                        <geom name="tip_left_pivot_slip" pos="0.038 0.00925 0.00" size="0.0024" type="sphere" rgba="0 0.7 0.1 1" friction="0.5 0.005 0.0001" solimp="0.95 0.95 0.01" solref="0.01 1" condim="4" margin="0.0" />
                                                        <geom name="tip_left_rubber" pos="0.025 0.00925 0" size="0.019 0.001 0.011" type="box" rgba="1.5 0.7 0.1 1" friction="1 0.08 0.0001" solimp="0.98 0.98 0.01 0.5 6" solref="0.01 1" condim="4" margin="0.0" />
                                                        
                                                        <body name="gripper_finger1_inner_knuckle_link" pos="-0.0430396 0.0375994 0">
                                                            <inertial pos="0 0 0" quat="0.707107 0.707107 0 0" mass="0.029951" diaginertia="3.9e-05 3.5e-05 5e-06" />
                                                            <joint name="gripper_finger1_inner_knuckle_joint" pos="0.0430396 -0.0375994 0" axis="0 0 1" limited="true" range="0 0.804" class="2F-85" />
                                                            <geom type="mesh" mesh="robotiq_85_inner_knuckle_link" /> 
                                                                                                   
                                                            <site name="gf1a_s" pos="0 0 0" rgba="0.9 0.1 0.1 1.0" size="0.002,0.002,0.002" />
                                                            
                                                        </body>
                                                    </body>                                            
                                                </body>
                                            </body>
                                            <body name="gripper_finger2_knuckle_link" pos="0.0306448 2.43685e-05 -0.116405" quat="-0.5 0.500398 -0.499602 -0.5">
                                                <inertial pos="-0.00243606 -0.0187741 0" quat="0.647436 0.284299 -0.647436 0.284299" mass="0.0458" diaginertia="4.11145e-05 2.69913e-05 1.81232e-05" />
                                                <joint name="robot0:gripper_finger2_joint" pos="0 0 0" axis="0 0 1" damping="5" limited="true" range="0 0.804" class="2F-85" />
                                                <geom type="mesh" mesh="robotiq_85_knuckle_link" />
                                                <body name="gripper_finger2_knuckle2_link" pos="0 0 0">
                                                    <joint name="gripper_finger2_joint2" pos="-0.00408552 -0.031486 0" axis="0 0 1" limited="true" range="0 0.804" class="2F-85" />
                                                    <geom pos="-0.00408552 -0.031486 0" type="mesh" mesh="robotiq_85_finger_link" />
                                                    <body name="gripper_finger2_finger_tip_link" pos="0.05 -0.0200 0">
                                                        <inertial pos="0 0 0" quat="0 0.707107 0 0.707107" mass="0.019555" diaginertia="6e-06 5e-06 2e-06" />
                                                        <joint name="gripper_finger2_finger_tip_joint" pos="-0.0066 -0.017245 0" stiffness="50" axis="0 0 1" limited="false" range="0 0.804" class="2F-85" />
                                                        <geom type="mesh" mesh="robotiq_85_finger_tip_link" friction="0.0 0.00 0.0000" solimp="0.99 0.99 0.01" solref="0.01 1" condim="4" margin="0.0" />
                                                        <geom name="tip_right_pivot" pos="0.038 0.00925 0.00" size="0.0018" type="sphere" rgba="0 0.7 0.1 1" friction="1.2 0.01 0.0001" solimp="0.99 0.99 0.01" solref="0.01 1" condim="4" margin="0.0" />
                                                        <geom name="tip_right_pivot_slip" pos="0.038 0.00925 0.00" size="0.0024" type="sphere" rgba="0 0.7 0.1 1" friction="0.5 0.005 0.0001" solimp="0.95 0.95 0.01" solref="0.01 1" condim="4" margin="0.0" />
                                                        <geom name="tip_right_rubber" pos="0.025 0.00925 0" size="0.019 0.001 0.011" type="box" rgba="1.5 0.7 0.1 1" friction="1 0.08 0.0001" solimp="0.98 0.98 0.01 0.5 6" solref="0.01 1" condim="4" margin="0.0" />
                                                        <body name="gripper_finger2_inner_knuckle_link" pos="-0.0430396 0.0375994 0">
                                                            <inertial pos="0 0 0" quat="0.707107 0.707107 0 0" mass="0.029951" diaginertia="3.9e-05 3.5e-05 5e-06" />
                                                            <joint name="gripper_finger2_inner_knuckle_joint" pos="0.0430396 -0.0375994 0" axis="0 0 1" limited="true" range="0 0.804" class="2F-85" />
                                                            <geom type="mesh" mesh="robotiq_85_inner_knuckle_link" /> 
                                                                                                   
                                                            <site name="gf2a_s" pos="0 0 0" rgba="0.9 0.1 0.1 1.0" size="0.002,0.002,0.002" />
                                                            
                                                        </body>
                                                    </body>                                            
                                                </body>
                                            </body>
                                        </body>
                                    </body>
                                </body>
                            </body>
                        </body>
                    </body>
                </body>
            </body>
            
           
            
                
            
            
        <body name="Table" pos="0.475 0.0 0.8"><geom size="0.6 0.3 0.015" type="box" rgba="0.8 0.2 0.1 1" friction="0.25 0.005 0.0001" solimp="0.95 0.95 0.01" solref="0.01 1" condim="4" margin="0.0" /><site name="target0" size="0.02 0.0001" rgba="0 1 0 1" type="cylinder" pos="-0.1 -0.25 0.015" /><geom size="0.0135 0.2" pos="-0.575 -0.27499999999999997 -0.2" type="cylinder" rgba="0.8 0.2 0.1 1" /><geom size="0.0135 0.2" pos="-0.575 0.27499999999999997 -0.2" type="cylinder" rgba="0.8 0.2 0.1 1" /><geom size="0.0135 0.2" pos="0.575 -0.27499999999999997 -0.2" type="cylinder" rgba="0.8 0.2 0.1 1" /><geom size="0.0135 0.2" pos="0.575 0.27499999999999997 -0.2" type="cylinder" rgba="0.8 0.2 0.1 1" /><geom name="spheret0" type="sphere" size="0.0001237177778418296" pos="0.4896798332700437 0.02002471271043693 0.015" rgba="1.0 1.0 1.0 1" friction="0.25 0.005 0.0001" solimp="0.95 0.95 0.01" solref="0.01 1" condim="4" margin="0.0" /><geom name="spheret1" type="sphere" size="9.377283698671477e-05" pos="-0.4917470739961373 0.08273270310853698 0.015" rgba="1.0 1.0 1.0 1" friction="0.25 0.005 0.0001" solimp="0.95 0.95 0.01" solref="0.01 1" condim="4" margin="0.0" /><geom name="spheret2" type="sphere" size="5.1889690662003375e-05" pos="0.5682963594050866 0.24227059924657873 0.015" rgba="1.0 1.0 1.0 1" friction="0.25 0.005 0.0001" solimp="0.95 0.95 0.01" solref="0.01 1" condim="4" margin="0.0" /><geom name="spheret3" type="sphere" size="7.657541982921114e-05" pos="0.5284118299125994 0.28411304120444575 0.015" rgba="1.0 1.0 1.0 1" friction="0.25 0.005 0.0001" solimp="0.95 0.95 0.01" solref="0.01 1" condim="4" margin="0.0" /><geom name="spheret4" type="sphere" size="0.00012234722270034764" pos="-0.3678594530039414 0.14549820670225988 0.015" rgba="1.0 1.0 1.0 1" friction="0.25 0.005 0.0001" solimp="0.95 0.95 0.01" solref="0.01 1" condim="4" margin="0.0" /><geom name="spheret5" type="sphere" size="7.696910892308759e-05" pos="0.4546527773641035 0.28861427366839704 0.015" rgba="1.0 1.0 1.0 1" friction="0.25 0.005 0.0001" solimp="0.95 0.95 0.01" solref="0.01 1" condim="4" margin="0.0" /><geom name="spheret6" type="sphere" size="0.0001254048517205173" pos="0.0306193846481706 -0.27438942967711777 0.015" rgba="1.0 1.0 1.0 1" friction="0.25 0.005 0.0001" solimp="0.95 0.95 0.01" solref="0.01 1" condim="4" margin="0.0" /><geom name="spheret7" type="sphere" size="0.0001604928762456266" pos="0.33129528350931736 0.09317158182942109 0.015" rgba="1.0 1.0 1.0 1" friction="0.25 0.005 0.0001" solimp="0.95 0.95 0.01" solref="0.01 1" condim="4" margin="0.0" /><geom name="spheret8" type="sphere" size="0.00017489656117388353" pos="0.33366026247361913 0.21503639634621935 0.015" rgba="1.0 1.0 1.0 1" friction="0.25 0.005 0.0001" solimp="0.95 0.95 0.01" solref="0.01 1" condim="4" margin="0.0" /><geom name="spheret9" type="sphere" size="0.00016902876920802802" pos="-0.3806495009052502 0.0404008323743264 0.015" rgba="1.0 1.0 1.0 1" friction="0.25 0.005 0.0001" solimp="0.95 0.95 0.01" solref="0.01 1" condim="4" margin="0.0" /><geom name="spheret10" type="sphere" size="0.00018211194206347792" pos="-0.5928304195938915 0.1826835609644994 0.015" rgba="1.0 1.0 1.0 1" friction="0.25 0.005 0.0001" solimp="0.95 0.95 0.01" solref="0.01 1" condim="4" margin="0.0" /><geom name="spheret11" type="sphere" size="0.0001399054132211354" pos="-0.5583224675583526 -0.08142072613782622 0.015" rgba="1.0 1.0 1.0 1" friction="0.25 0.005 0.0001" solimp="0.95 0.95 0.01" solref="0.01 1" condim="4" margin="0.0" /><geom name="spheret12" type="sphere" size="9.80810341784036e-05" pos="-0.13889031298967935 0.036943785934993034 0.015" rgba="1.0 1.0 1.0 1" friction="0.25 0.005 0.0001" solimp="0.95 0.95 0.01" solref="0.01 1" condim="4" margin="0.0" /><geom name="spheret13" type="sphere" size="7.725894619096901e-05" pos="-0.3044501180040333 -0.1384044187328998 0.015" rgba="1.0 1.0 1.0 1" friction="0.25 0.005 0.0001" solimp="0.95 0.95 0.01" solref="0.01 1" condim="4" margin="0.0" /><geom name="spheret14" type="sphere" size="9.69951927641365e-05" pos="-0.533691369098555 0.2639080892469973 0.015" rgba="1.0 1.0 1.0 1" friction="0.25 0.005 0.0001" solimp="0.95 0.95 0.01" solref="0.01 1" condim="4" margin="0.0" /><geom name="spheret15" type="sphere" size="0.00014422428754272404" pos="0.48538130660646106 0.0696531208523426 0.015" rgba="1.0 1.0 1.0 1" friction="0.25 0.005 0.0001" solimp="0.95 0.95 0.01" solref="0.01 1" condim="4" margin="0.0" /><geom name="spheret16" type="sphere" size="0.00017686396545188335" pos="-0.14549951339655803 -0.26657487756658343 0.015" rgba="1.0 1.0 1.0 1" friction="0.25 0.005 0.0001" solimp="0.95 0.95 0.01" solref="0.01 1" condim="4" margin="0.0" /><geom name="spheret17" type="sphere" size="0.00018661174149484222" pos="-0.23054160555962705 0.2778185637832446 0.015" rgba="1.0 1.0 1.0 1" friction="0.25 0.005 0.0001" solimp="0.95 0.95 0.01" solref="0.01 1" condim="4" margin="0.0" /><geom name="spheret18" type="sphere" size="7.052273000562488e-05" pos="-0.4498360712432898 -0.15162738993837133 0.015" rgba="1.0 1.0 1.0 1" friction="0.25 0.005 0.0001" solimp="0.95 0.95 0.01" solref="0.01 1" condim="4" margin="0.0" /><geom name="spheret19" type="sphere" size="0.0001733762869346472" pos="-0.34007209465365734 0.03211704433406726 0.015" rgba="1.0 1.0 1.0 1" friction="0.25 0.005 0.0001" solimp="0.95 0.95 0.01" solref="0.01 1" condim="4" margin="0.0" /><geom name="spheret20" type="sphere" size="9.119433301110523e-05" pos="0.22748136256025897 0.10340606132608493 0.015" rgba="1.0 1.0 1.0 1" friction="0.25 0.005 0.0001" solimp="0.95 0.95 0.01" solref="0.01 1" condim="4" margin="0.0" /><geom name="spheret21" type="sphere" size="0.00012032477266069025" pos="-0.07546622552254345 -0.2453596085550581 0.015" rgba="1.0 1.0 1.0 1" friction="0.25 0.005 0.0001" solimp="0.95 0.95 0.01" solref="0.01 1" condim="4" margin="0.0" /><geom name="spheret22" type="sphere" size="0.0001891947486399117" pos="-0.3863669970861955 -0.05171637455256564 0.015" rgba="1.0 1.0 1.0 1" friction="0.25 0.005 0.0001" solimp="0.95 0.95 0.01" solref="0.01 1" condim="4" margin="0.0" /><geom name="spheret23" type="sphere" size="0.00015915889164218384" pos="0.27383728010970776 0.20347697601311449 0.015" rgba="1.0 1.0 1.0 1" friction="0.25 0.005 0.0001" solimp="0.95 0.95 0.01" solref="0.01 1" condim="4" margin="0.0" /><geom name="spheret24" type="sphere" size="0.00010589772676824698" pos="0.48362762089456923 0.20947033698156575 0.015" rgba="1.0 1.0 1.0 1" friction="0.25 0.005 0.0001" solimp="0.95 0.95 0.01" solref="0.01 1" condim="4" margin="0.0" /><geom name="spheret25" type="sphere" size="0.0001288243553154822" pos="0.3044723767601992 -0.29762485997232035 0.015" rgba="1.0 1.0 1.0 1" friction="0.25 0.005 0.0001" solimp="0.95 0.95 0.01" solref="0.01 1" condim="4" margin="0.0" /><geom name="spheret26" type="sphere" size="0.0001301106826402596" pos="0.22383640533032223 -0.05749673886704437 0.015" rgba="1.0 1.0 1.0 1" friction="0.25 0.005 0.0001" solimp="0.95 0.95 0.01" solref="0.01 1" condim="4" margin="0.0" /><geom name="spheret27" type="sphere" size="0.00017505683258308116" pos="0.5127007780013747 0.0778035020990589 0.015" rgba="1.0 1.0 1.0 1" friction="0.25 0.005 0.0001" solimp="0.95 0.95 0.01" solref="0.01 1" condim="4" margin="0.0" /><geom name="spheret28" type="sphere" size="0.00018812142806304917" pos="0.582165497517079 -0.004518967714918609 0.015" rgba="1.0 1.0 1.0 1" friction="0.25 0.005 0.0001" solimp="0.95 0.95 0.01" solref="0.01 1" condim="4" margin="0.0" /><geom name="spheret29" type="sphere" size="0.00012537945693259374" pos="0.10595555655918298 0.14287161198746162 0.015" rgba="1.0 1.0 1.0 1" friction="0.25 0.005 0.0001" solimp="0.95 0.95 0.01" solref="0.01 1" condim="4" margin="0.0" /><geom name="spheret30" type="sphere" size="8.244351379715998e-05" pos="0.5562430147275746 -0.2079231898306692 0.015" rgba="1.0 1.0 1.0 1" friction="0.25 0.005 0.0001" solimp="0.95 0.95 0.01" solref="0.01 1" condim="4" margin="0.0" /><geom name="spheret31" type="sphere" size="0.00018527497905755817" pos="-0.13576596980017924 -0.16852050497567364 0.015" rgba="1.0 1.0 1.0 1" friction="0.25 0.005 0.0001" solimp="0.95 0.95 0.01" solref="0.01 1" condim="4" margin="0.0" /><geom name="spheret32" type="sphere" size="7.233111089943622e-05" pos="0.11401610446581645 0.12489673954663538 0.015" rgba="1.0 1.0 1.0 1" friction="0.25 0.005 0.0001" solimp="0.95 0.95 0.01" solref="0.01 1" condim="4" margin="0.0" /><geom name="spheret33" type="sphere" size="8.542974950819513e-05" pos="-0.15637726540897262 0.20678432072993141 0.015" rgba="1.0 1.0 1.0 1" friction="0.25 0.005 0.0001" solimp="0.95 0.95 0.01" solref="0.01 1" condim="4" margin="0.0" /><geom name="spheret34" type="sphere" size="0.0001087673982629645" pos="-0.3884970487448003 -0.23921940155365135 0.015" rgba="1.0 1.0 1.0 1" friction="0.25 0.005 0.0001" solimp="0.95 0.95 0.01" solref="0.01 1" condim="4" margin="0.0" /><geom name="spheret35" type="sphere" size="0.00016312309303346607" pos="0.32318794390045724 -0.1329631547649857 0.015" rgba="1.0 1.0 1.0 1" friction="0.25 0.005 0.0001" solimp="0.95 0.95 0.01" solref="0.01 1" condim="4" margin="0.0" /><geom name="spheret36" type="sphere" size="0.00015149934583501835" pos="-0.03514005072276949 0.044531577884175555 0.015" rgba="1.0 1.0 1.0 1" friction="0.25 0.005 0.0001" solimp="0.95 0.95 0.01" solref="0.01 1" condim="4" margin="0.0" /><geom name="spheret37" type="sphere" size="0.00010778682312426298" pos="-0.4366381787299395 -0.043064277955319974 0.015" rgba="1.0 1.0 1.0 1" friction="0.25 0.005 0.0001" solimp="0.95 0.95 0.01" solref="0.01 1" condim="4" margin="0.0" /><geom name="spheret38" type="sphere" size="9.66745222596483e-05" pos="0.35849501719128074 0.24707393855953924 0.015" rgba="1.0 1.0 1.0 1" friction="0.25 0.005 0.0001" solimp="0.95 0.95 0.01" solref="0.01 1" condim="4" margin="0.0" /><geom name="spheret39" type="sphere" size="0.0001797434190318198" pos="0.19849098309952207 -0.1311959655572115 0.015" rgba="1.0 1.0 1.0 1" friction="0.25 0.005 0.0001" solimp="0.95 0.95 0.01" solref="0.01 1" condim="4" margin="0.0" /><geom name="spheret40" type="sphere" size="0.00014969135928507703" pos="0.2817361039195634 0.2996916358869797 0.015" rgba="1.0 1.0 1.0 1" friction="0.25 0.005 0.0001" solimp="0.95 0.95 0.01" solref="0.01 1" condim="4" margin="0.0" /><geom name="spheret41" type="sphere" size="5.825150865062639e-05" pos="0.33201490463800487 0.012515229236297332 0.015" rgba="1.0 1.0 1.0 1" friction="0.25 0.005 0.0001" solimp="0.95 0.95 0.01" solref="0.01 1" condim="4" margin="0.0" /><geom name="spheret42" type="sphere" size="0.0001628764763897018" pos="0.25743465699538115 -0.06092254482440157 0.015" rgba="1.0 1.0 1.0 1" friction="0.25 0.005 0.0001" solimp="0.95 0.95 0.01" solref="0.01 1" condim="4" margin="0.0" /><geom name="spheret43" type="sphere" size="6.536279401481736e-05" pos="0.14802745319247823 0.28995300779797967 0.015" rgba="1.0 1.0 1.0 1" friction="0.25 0.005 0.0001" solimp="0.95 0.95 0.01" solref="0.01 1" condim="4" margin="0.0" /><geom name="spheret44" type="sphere" size="9.808176100652662e-05" pos="-0.01615108166979151 0.29359436857435567 0.015" rgba="1.0 1.0 1.0 1" friction="0.25 0.005 0.0001" solimp="0.95 0.95 0.01" solref="0.01 1" condim="4" margin="0.0" /><geom name="spheret45" type="sphere" size="6.386304608293254e-05" pos="0.2551958434308518 0.11894138380755742 0.015" rgba="1.0 1.0 1.0 1" friction="0.25 0.005 0.0001" solimp="0.95 0.95 0.01" solref="0.01 1" condim="4" margin="0.0" /><geom name="spheret46" type="sphere" size="9.06050606415403e-05" pos="-0.5739793317395047 0.06989103375203454 0.015" rgba="1.0 1.0 1.0 1" friction="0.25 0.005 0.0001" solimp="0.95 0.95 0.01" solref="0.01 1" condim="4" margin="0.0" /><geom name="spheret47" type="sphere" size="0.00017463504755675234" pos="0.4609752395554064 0.2795175935471787 0.015" rgba="1.0 1.0 1.0 1" friction="0.25 0.005 0.0001" solimp="0.95 0.95 0.01" solref="0.01 1" condim="4" margin="0.0" /><geom name="spheret48" type="sphere" size="0.00015770415052639828" pos="-0.2275636183953344 -0.1317805676683619 0.015" rgba="1.0 1.0 1.0 1" friction="0.25 0.005 0.0001" solimp="0.95 0.95 0.01" solref="0.01 1" condim="4" margin="0.0" /><geom name="spheret49" type="sphere" size="9.676137259424729e-05" pos="-0.42870433501333505 0.20099877211581435 0.015" rgba="1.0 1.0 1.0 1" friction="0.25 0.005 0.0001" solimp="0.95 0.95 0.01" solref="0.01 1" condim="4" margin="0.0" /><geom name="spheret50" type="sphere" size="0.00019860835141542" pos="0.26904537728102795 -0.0656752568658274 0.015" rgba="1.0 1.0 1.0 1" friction="0.25 0.005 0.0001" solimp="0.95 0.95 0.01" solref="0.01 1" condim="4" margin="0.0" /><geom name="spheret51" type="sphere" size="0.00017110697412073638" pos="0.24746783745654366 0.139095682083062 0.015" rgba="1.0 1.0 1.0 1" friction="0.25 0.005 0.0001" solimp="0.95 0.95 0.01" solref="0.01 1" condim="4" margin="0.0" /><geom name="spheret52" type="sphere" size="0.00019555827892230114" pos="0.38785114022334155 0.106098989969727 0.015" rgba="1.0 1.0 1.0 1" friction="0.25 0.005 0.0001" solimp="0.95 0.95 0.01" solref="0.01 1" condim="4" margin="0.0" /><geom name="spheret53" type="sphere" size="0.0001302879426591689" pos="-0.526185510763877 -0.2232656375405585 0.015" rgba="1.0 1.0 1.0 1" friction="0.25 0.005 0.0001" solimp="0.95 0.95 0.01" solref="0.01 1" condim="4" margin="0.0" /><geom name="spheret54" type="sphere" size="0.00014125223960370598" pos="-0.3431883974657649 0.09275942681573068 0.015" rgba="1.0 1.0 1.0 1" friction="0.25 0.005 0.0001" solimp="0.95 0.95 0.01" solref="0.01 1" condim="4" margin="0.0" /><geom name="spheret55" type="sphere" size="0.0001380061544975411" pos="0.09822819271670702 0.18964352662657752 0.015" rgba="1.0 1.0 1.0 1" friction="0.25 0.005 0.0001" solimp="0.95 0.95 0.01" solref="0.01 1" condim="4" margin="0.0" /><geom name="spheret56" type="sphere" size="0.00019136359324705424" pos="-0.27009656921977776 0.17322187886665724 0.015" rgba="1.0 1.0 1.0 1" friction="0.25 0.005 0.0001" solimp="0.95 0.95 0.01" solref="0.01 1" condim="4" margin="0.0" /><geom name="spheret57" type="sphere" size="0.00010920912441449702" pos="0.520950169985639 -0.178595454586277 0.015" rgba="1.0 1.0 1.0 1" friction="0.25 0.005 0.0001" solimp="0.95 0.95 0.01" solref="0.01 1" condim="4" margin="0.0" /><geom name="spheret58" type="sphere" size="5.2262133277432726e-05" pos="0.08636229639472837 0.02931177767805515 0.015" rgba="1.0 1.0 1.0 1" friction="0.25 0.005 0.0001" solimp="0.95 0.95 0.01" solref="0.01 1" condim="4" margin="0.0" /><geom name="spheret59" type="sphere" size="0.00011681916392378218" pos="-0.4828494586196207 0.2684027746379573 0.015" rgba="1.0 1.0 1.0 1" friction="0.25 0.005 0.0001" solimp="0.95 0.95 0.01" solref="0.01 1" condim="4" margin="0.0" /><geom name="spheret60" type="sphere" size="7.523940975695173e-05" pos="-0.01669051742151284 0.09232651926031621 0.015" rgba="1.0 1.0 1.0 1" friction="0.25 0.005 0.0001" solimp="0.95 0.95 0.01" solref="0.01 1" condim="4" margin="0.0" /><geom name="spheret61" type="sphere" size="0.00011476168377994245" pos="-0.4942821028968844 0.2252345320859252 0.015" rgba="1.0 1.0 1.0 1" friction="0.25 0.005 0.0001" solimp="0.95 0.95 0.01" solref="0.01 1" condim="4" margin="0.0" /><geom name="spheret62" type="sphere" size="0.0001770465575097398" pos="-0.41063603603283794 -0.2340186294861865 0.015" rgba="1.0 1.0 1.0 1" friction="0.25 0.005 0.0001" solimp="0.95 0.95 0.01" solref="0.01 1" condim="4" margin="0.0" /><geom name="spheret63" type="sphere" size="6.034444107574615e-05" pos="-0.5014491583026371 -0.14241230887488604 0.015" rgba="1.0 1.0 1.0 1" friction="0.25 0.005 0.0001" solimp="0.95 0.95 0.01" solref="0.01 1" condim="4" margin="0.0" /><geom name="spheret64" type="sphere" size="0.00015794548529367983" pos="0.5498437948860583 0.21269138842126595 0.015" rgba="1.0 1.0 1.0 1" friction="0.25 0.005 0.0001" solimp="0.95 0.95 0.01" solref="0.01 1" condim="4" margin="0.0" /><geom name="spheret65" type="sphere" size="0.00015947942250081309" pos="-0.4720187246804022 0.05081889184810101 0.015" rgba="1.0 1.0 1.0 1" friction="0.25 0.005 0.0001" solimp="0.95 0.95 0.01" solref="0.01 1" condim="4" margin="0.0" /><geom name="spheret66" type="sphere" size="0.00015016686449156243" pos="-0.5817535874598634 -0.27751065579527723 0.015" rgba="1.0 1.0 1.0 1" friction="0.25 0.005 0.0001" solimp="0.95 0.95 0.01" solref="0.01 1" condim="4" margin="0.0" /><geom name="spheret67" type="sphere" size="0.0001268521788405205" pos="-0.5959083445650659 -0.09622184827249738 0.015" rgba="1.0 1.0 1.0 1" friction="0.25 0.005 0.0001" solimp="0.95 0.95 0.01" solref="0.01 1" condim="4" margin="0.0" /><geom name="spheret68" type="sphere" size="0.00012279910072716867" pos="-0.27611530811407964 -0.2176856960972175 0.015" rgba="1.0 1.0 1.0 1" friction="0.25 0.005 0.0001" solimp="0.95 0.95 0.01" solref="0.01 1" condim="4" margin="0.0" /><geom name="spheret69" type="sphere" size="0.00014188744383081617" pos="-0.34104674541975705 -0.1027507496451806 0.015" rgba="1.0 1.0 1.0 1" friction="0.25 0.005 0.0001" solimp="0.95 0.95 0.01" solref="0.01 1" condim="4" margin="0.0" /><geom name="spheret70" type="sphere" size="0.00012128532656328477" pos="-0.553933956581658 0.07926438182042123 0.015" rgba="1.0 1.0 1.0 1" friction="0.25 0.005 0.0001" solimp="0.95 0.95 0.01" solref="0.01 1" condim="4" margin="0.0" /><geom name="spheret71" type="sphere" size="7.269901693006819e-05" pos="-0.4550195178323306 -0.10483339200506095 0.015" rgba="1.0 1.0 1.0 1" friction="0.25 0.005 0.0001" solimp="0.95 0.95 0.01" solref="0.01 1" condim="4" margin="0.0" /><geom name="spheret72" type="sphere" size="0.00019873716000947354" pos="0.02321449412529164 -0.26158369039725177 0.015" rgba="1.0 1.0 1.0 1" friction="0.25 0.005 0.0001" solimp="0.95 0.95 0.01" solref="0.01 1" condim="4" margin="0.0" /><geom name="spheret73" type="sphere" size="0.00012482689056900705" pos="0.5786920513015398 0.20261849396886683 0.015" rgba="1.0 1.0 1.0 1" friction="0.25 0.005 0.0001" solimp="0.95 0.95 0.01" solref="0.01 1" condim="4" margin="0.0" /><geom name="spheret74" type="sphere" size="9.310814684625402e-05" pos="0.053851032980806846 -0.06139256473190716 0.015" rgba="1.0 1.0 1.0 1" friction="0.25 0.005 0.0001" solimp="0.95 0.95 0.01" solref="0.01 1" condim="4" margin="0.0" /><geom name="spheret75" type="sphere" size="0.0001757351824530622" pos="-0.46579028700477026 0.10592995707572966 0.015" rgba="1.0 1.0 1.0 1" friction="0.25 0.005 0.0001" solimp="0.95 0.95 0.01" solref="0.01 1" condim="4" margin="0.0" /><geom name="spheret76" type="sphere" size="8.974701325178605e-05" pos="0.33418448626223607 -0.2110398216847068 0.015" rgba="1.0 1.0 1.0 1" friction="0.25 0.005 0.0001" solimp="0.95 0.95 0.01" solref="0.01 1" condim="4" margin="0.0" /><geom name="spheret77" type="sphere" size="0.00016656727688199705" pos="0.33022613749130225 0.17308758638627159 0.015" rgba="1.0 1.0 1.0 1" friction="0.25 0.005 0.0001" solimp="0.95 0.95 0.01" solref="0.01 1" condim="4" margin="0.0" /><geom name="spheret78" type="sphere" size="0.0001467076959953926" pos="0.09724399609261625 0.06182765443128241 0.015" rgba="1.0 1.0 1.0 1" friction="0.25 0.005 0.0001" solimp="0.95 0.95 0.01" solref="0.01 1" condim="4" margin="0.0" /><geom name="spheret79" type="sphere" size="7.237051056877503e-05" pos="-0.3370958104711734 -0.05169413218504057 0.015" rgba="1.0 1.0 1.0 1" friction="0.25 0.005 0.0001" solimp="0.95 0.95 0.01" solref="0.01 1" condim="4" margin="0.0" /><geom name="spheret80" type="sphere" size="0.00019631432813449102" pos="0.3117799482733724 -0.2408737639312402 0.015" rgba="1.0 1.0 1.0 1" friction="0.25 0.005 0.0001" solimp="0.95 0.95 0.01" solref="0.01 1" condim="4" margin="0.0" /><geom name="spheret81" type="sphere" size="5.39198158262317e-05" pos="-0.10804399888738436 -0.10135530255501604 0.015" rgba="1.0 1.0 1.0 1" friction="0.25 0.005 0.0001" solimp="0.95 0.95 0.01" solref="0.01 1" condim="4" margin="0.0" /><geom name="spheret82" type="sphere" size="6.771469586687607e-05" pos="-0.10469793399877941 -0.206870992860924 0.015" rgba="1.0 1.0 1.0 1" friction="0.25 0.005 0.0001" solimp="0.95 0.95 0.01" solref="0.01 1" condim="4" margin="0.0" /><geom name="spheret83" type="sphere" size="0.00016187560749033136" pos="-0.20588893043842432 0.12882655915970997 0.015" rgba="1.0 1.0 1.0 1" friction="0.25 0.005 0.0001" solimp="0.95 0.95 0.01" solref="0.01 1" condim="4" margin="0.0" /><geom name="spheret84" type="sphere" size="0.0001937872119795295" pos="-0.37213610257243923 0.10807142117943497 0.015" rgba="1.0 1.0 1.0 1" friction="0.25 0.005 0.0001" solimp="0.95 0.95 0.01" solref="0.01 1" condim="4" margin="0.0" /><geom name="spheret85" type="sphere" size="6.75051810899556e-05" pos="-0.45485931649366246 -0.15104468496867463 0.015" rgba="1.0 1.0 1.0 1" friction="0.25 0.005 0.0001" solimp="0.95 0.95 0.01" solref="0.01 1" condim="4" margin="0.0" /><geom name="spheret86" type="sphere" size="0.00012458646021035286" pos="-0.04606228425956993 -0.062154389350113 0.015" rgba="1.0 1.0 1.0 1" friction="0.25 0.005 0.0001" solimp="0.95 0.95 0.01" solref="0.01 1" condim="4" margin="0.0" /><geom name="spheret87" type="sphere" size="9.977407872887553e-05" pos="0.5130972340600429 -0.18377775170826202 0.015" rgba="1.0 1.0 1.0 1" friction="0.25 0.005 0.0001" solimp="0.95 0.95 0.01" solref="0.01 1" condim="4" margin="0.0" /><geom name="spheret88" type="sphere" size="0.00012456428864744765" pos="-0.5172569394790647 -0.11926713682802487 0.015" rgba="1.0 1.0 1.0 1" friction="0.25 0.005 0.0001" solimp="0.95 0.95 0.01" solref="0.01 1" condim="4" margin="0.0" /><geom name="spheret89" type="sphere" size="0.00013852898668295343" pos="0.5561518699121278 -0.16780913492905083 0.015" rgba="1.0 1.0 1.0 1" friction="0.25 0.005 0.0001" solimp="0.95 0.95 0.01" solref="0.01 1" condim="4" margin="0.0" /><geom name="spheret90" type="sphere" size="0.0001768233781609519" pos="0.43458153757089446 -0.2184113094734363 0.015" rgba="1.0 1.0 1.0 1" friction="0.25 0.005 0.0001" solimp="0.95 0.95 0.01" solref="0.01 1" condim="4" margin="0.0" /><geom name="spheret91" type="sphere" size="0.0001858710712569026" pos="-0.10319092672092911 0.02782990594461987 0.015" rgba="1.0 1.0 1.0 1" friction="0.25 0.005 0.0001" solimp="0.95 0.95 0.01" solref="0.01 1" condim="4" margin="0.0" /><geom name="spheret92" type="sphere" size="0.0001523469569336082" pos="-0.1820845526749949 -0.02105409743151243 0.015" rgba="1.0 1.0 1.0 1" friction="0.25 0.005 0.0001" solimp="0.95 0.95 0.01" solref="0.01 1" condim="4" margin="0.0" /><geom name="spheret93" type="sphere" size="5.230180161955201e-05" pos="-0.39490834175307066 0.09443465503831605 0.015" rgba="1.0 1.0 1.0 1" friction="0.25 0.005 0.0001" solimp="0.95 0.95 0.01" solref="0.01 1" condim="4" margin="0.0" /><geom name="spheret94" type="sphere" size="0.00019575866966506242" pos="-0.38351664566153276 -0.07846446329781115 0.015" rgba="1.0 1.0 1.0 1" friction="0.25 0.005 0.0001" solimp="0.95 0.95 0.01" solref="0.01 1" condim="4" margin="0.0" /><geom name="spheret95" type="sphere" size="0.00017865602519130032" pos="-0.46345760715017237 -0.17709011488753834 0.015" rgba="1.0 1.0 1.0 1" friction="0.25 0.005 0.0001" solimp="0.95 0.95 0.01" solref="0.01 1" condim="4" margin="0.0" /><geom name="spheret96" type="sphere" size="0.00016244967087477102" pos="0.2672818393553089 -0.15569001022273443 0.015" rgba="1.0 1.0 1.0 1" friction="0.25 0.005 0.0001" solimp="0.95 0.95 0.01" solref="0.01 1" condim="4" margin="0.0" /><geom name="spheret97" type="sphere" size="0.00011819620040128096" pos="-0.41743218659033776 0.2052774778634971 0.015" rgba="1.0 1.0 1.0 1" friction="0.25 0.005 0.0001" solimp="0.95 0.95 0.01" solref="0.01 1" condim="4" margin="0.0" /><geom name="spheret98" type="sphere" size="6.309791474430664e-05" pos="0.012573486149301094 0.1709075361408567 0.015" rgba="1.0 1.0 1.0 1" friction="0.25 0.005 0.0001" solimp="0.95 0.95 0.01" solref="0.01 1" condim="4" margin="0.0" /><geom name="spheret99" type="sphere" size="0.00016808498014436854" pos="0.4497538972118754 -0.07452859542937146 0.015" rgba="1.0 1.0 1.0 1" friction="0.25 0.005 0.0001" solimp="0.95 0.95 0.01" solref="0.01 1" condim="4" margin="0.0" /></body><body name="ConSurf" pos="0.45 0.0 0.8400000000000001"><geom name="ConSurf" type="box" size="0.035 0.015 0.025" rgba="0.999 0.999 0.999 1" friction="0.45 0.005 0.0001" solimp="0.95 0.95 0.01" solref="0.01 1" condim="3" priority="2" margin="0.0" /><joint name="object0:joint_x" pos="0 0 0" type="slide" axis="1 0 0" damping="0.01" /><joint name="object0:joint_y" pos="0 0 0" type="slide" axis="0 1 0" damping="0.01" /><joint name="object0:joint_z" pos="0 0 0" type="slide" axis="0 0 1" damping="0.01" /><joint name="object0:joint_r" pos="0 0 0" type="hinge" axis="1 0 0" damping="0.01" /><joint name="object0:joint_p" pos="0 0 0" type="hinge" axis="0 1 0" damping="0.01" /><joint name="object0:joint_yw" pos="0 0 0" type="hinge" axis="0 0 1" damping="0.01" /><site name="object0" size="0.0001 0.0001" rgba="0 1 0 1" type="cylinder" pos="0 0 -0.025" /></body></worldbody>
        <equality>
            <tendon tendon1="gf1_t" polycoef="0 1 0 0 0" solref="0.01 1" solimp="0.99 0.99 0.001 0.5 2" />
            <tendon tendon1="gf2_t" polycoef="0 1 0 0 0" solref="0.01 1" solimp="0.99 0.99 0.001 0.5 2" />
        </equality>
        <tendon>               
            <spatial name="gf1_t" width="0.00002" rgba=".9 .9 .9 1" stiffness="10" damping="0.2" frictionloss="0">
                <site site="gf1a_s" />
                <site site="gf1b_s" />
            </spatial>
            <spatial name="gf2_t" width="0.00002" rgba=".9 .9 .9 1" stiffness="10" damping="0.2" frictionloss="0">
                <site site="gf2a_s" />
                <site site="gf2b_s" />
            </spatial>
        </tendon>        
        <actuator>
            
            
            <motor name="Joint1" gear="3" joint="robot0:joint_1" ctrllimited="true" ctrlrange="-39 39" />
            <motor name="Joint2" gear="3" joint="robot0:joint_2" ctrllimited="true" ctrlrange="-39 39" />
            <motor name="Joint3" gear="3" joint="robot0:joint_3" ctrllimited="true" ctrlrange="-39 39" />
            <motor name="Joint4" gear="3" joint="robot0:joint_4" ctrllimited="true" ctrlrange="-39 39" />
            <motor name="Joint5" gear="3" joint="robot0:joint_5" ctrllimited="true" ctrlrange="-19 19" />
            <motor name="Joint6" gear="3" joint="robot0:joint_6" ctrllimited="true" ctrlrange="-19 19" />
            <motor name="Joint7" gear="3" joint="robot0:joint_7" ctrllimited="true" ctrlrange="-19 19" />
            <position name="JointGL" gear="1" kp="80" joint="robot0:gripper_finger1_joint" ctrllimited="true" ctrlrange="0 1.5" forcelimited="false" forcerange="0 5" />
            <position name="JointGR" gear="1" kp="80" joint="robot0:gripper_finger2_joint" ctrllimited="true" ctrlrange="0 1.5" forcelimited="false" forcerange="0 5" />
        </actuator>
    </mujoco>

    